<?xml version="1.0"?>
<sdf version='1.7'>
  <world name='default'>
    <light name='sun' type='directional'>
      <cast_shadows>1</cast_shadows>
      <pose>0 0 10 0 -0 0</pose>
      <diffuse>0.8 0.8 0.8 1</diffuse>
      <specular>0.1 0.1 0.1 1</specular>
      <attenuation>
        <range>1000</range>
        <constant>0.9</constant>
        <linear>0.01</linear>
        <quadratic>0.001</quadratic>
      </attenuation>
      <direction>-0.5 0.5 -1</direction>
      <spot>
        <inner_angle>0</inner_angle>
        <outer_angle>0</outer_angle>
        <falloff>0</falloff>
      </spot>
    </light>
    <gravity>0 0 -9.8</gravity>
    <magnetic_field>6e-06 2.3e-05 -4.2e-05</magnetic_field>
    <atmosphere type='adiabatic'/>
    <physics name='default_physics' default='0' type='ode'>
      <max_step_size>0.001</max_step_size>
      <real_time_factor>1</real_time_factor>
      <real_time_update_rate>1000</real_time_update_rate>
    </physics>
    <scene>
      <ambient>0.4 0.4 0.4 1</ambient>
      <background>0.7 0.7 0.7 1</background>
      <shadows>1</shadows>
    </scene>
    <spherical_coordinates>
      <surface_model>EARTH_WGS84</surface_model>
      <latitude_deg>0</latitude_deg>
      <longitude_deg>0</longitude_deg>
      <elevation>0</elevation>
      <heading_deg>0</heading_deg>
    </spherical_coordinates>
    <model name='yellow line_0'>
      <static>1</static>
      <link name='link_ground'>
        <collision name='collision'>
          <geometry>
            <plane>
              <normal>0 0 1</normal>
              <size>0.1 2.5</size>
            </plane>
          </geometry>
          <surface>
            <friction>
              <ode>
                <mu>100</mu>
                <mu2>50</mu2>
              </ode>
              <torsional>
                <ode/>
              </torsional>
            </friction>
            <contact>
              <ode/>
            </contact>
            <bounce/>
          </surface>
          <max_contacts>10</max_contacts>
        </collision>
        <visual name='visual_ground'>
          <cast_shadows>0</cast_shadows>
          <geometry>
            <plane>
              <normal>0 0 1</normal>
              <size>0.1 2.5</size>
            </plane>
          </geometry>
          <material>
            <script>
              <uri>file://media/materials/scripts/gazebo.material</uri>
              <name>Gazebo/Yellow</name>
            </script>
          </material>
        </visual>
        <self_collide>0</self_collide>
        <kinematic>0</kinematic>
        <gravity>1</gravity>
        <enable_wind>0</enable_wind>
      </link>
      <pose>1.21409 0.311502 0 0 -0 0</pose>
    </model>
    <model name='yellow line_1'>
      <static>1</static>
      <link name='link_ground'>
        <collision name='collision'>
          <geometry>
            <plane>
              <normal>0 0 1</normal>
              <size>0.1 1</size>
            </plane>
          </geometry>
          <surface>
            <friction>
              <ode>
                <mu>100</mu>
                <mu2>50</mu2>
              </ode>
              <torsional>
                <ode/>
              </torsional>
            </friction>
            <contact>
              <ode/>
            </contact>
            <bounce/>
          </surface>
          <max_contacts>10</max_contacts>
        </collision>
        <visual name='visual_ground'>
          <cast_shadows>0</cast_shadows>
          <geometry>
            <plane>
              <normal>0 0 1</normal>
              <size>0.1 1</size>
            </plane>
          </geometry>
          <material>
            <script>
              <uri>file://media/materials/scripts/gazebo.material</uri>
              <name>Gazebo/Yellow</name>
            </script>
          </material>
        </visual>
        <self_collide>0</self_collide>
        <kinematic>0</kinematic>
        <gravity>1</gravity>
        <enable_wind>0</enable_wind>
      </link>
      <pose>2.46719 0.449585 0 0 -0 0</pose>
    </model>
    <model name='yellow line_2'>
      <static>1</static>
      <link name='link_ground'>
        <collision name='collision'>
          <geometry>
            <plane>
              <normal>0 0 1</normal>
              <size>0.1 2.5</size>
            </plane>
          </geometry>
          <surface>
            <friction>
              <ode>
                <mu>100</mu>
                <mu2>50</mu2>
              </ode>
              <torsional>
                <ode/>
              </torsional>
            </friction>
            <contact>
              <ode/>
            </contact>
            <bounce/>
          </surface>
          <max_contacts>10</max_contacts>
        </collision>
        <visual name='visual_ground'>
          <cast_shadows>0</cast_shadows>
          <geometry>
            <plane>
              <normal>0 0 1</normal>
              <size>0.1 2.5</size>
            </plane>
          </geometry>
          <material>
            <script>
              <uri>file://media/materials/scripts/gazebo.material</uri>
              <name>Gazebo/Yellow</name>
            </script>
          </material>
        </visual>
        <self_collide>0</self_collide>
        <kinematic>0</kinematic>
        <gravity>1</gravity>
        <enable_wind>0</enable_wind>
      </link>
      <pose>3.08297 1.87937 0 0 -0 0</pose>
    </model>
    <model name='yellow line_3'>
      <static>1</static>
      <link name='link_ground'>
        <collision name='collision'>
          <geometry>
            <plane>
              <normal>0 0 1</normal>
              <size>0.1 2</size>
            </plane>
          </geometry>
          <surface>
            <friction>
              <ode>
                <mu>100</mu>
                <mu2>50</mu2>
              </ode>
              <torsional>
                <ode/>
              </torsional>
            </friction>
            <contact>
              <ode/>
            </contact>
            <bounce/>
          </surface>
          <max_contacts>10</max_contacts>
        </collision>
        <visual name='visual_ground'>
          <cast_shadows>0</cast_shadows>
          <geometry>
            <plane>
              <normal>0 0 1</normal>
              <size>0.1 2</size>
            </plane>
          </geometry>
          <material>
            <script>
              <uri>file://media/materials/scripts/gazebo.material</uri>
              <name>Gazebo/Yellow</name>
            </script>
          </material>
        </visual>
        <self_collide>0</self_collide>
        <kinematic>0</kinematic>
        <gravity>1</gravity>
        <enable_wind>0</enable_wind>
      </link>
      <pose>2.51706 4.05198 0 0 -0 0</pose>
    </model>
    <model name='yellow line_4'>
      <static>1</static>
      <link name='link_ground'>
        <collision name='collision'>
          <geometry>
            <plane>
              <normal>0 0 1</normal>
              <size>0.1 2</size>
            </plane>
          </geometry>
          <surface>
            <friction>
              <ode>
                <mu>100</mu>
                <mu2>50</mu2>
              </ode>
              <torsional>
                <ode/>
              </torsional>
            </friction>
            <contact>
              <ode/>
            </contact>
            <bounce/>
          </surface>
          <max_contacts>10</max_contacts>
        </collision>
        <visual name='visual_ground'>
          <cast_shadows>0</cast_shadows>
          <geometry>
            <plane>
              <normal>0 0 1</normal>
              <size>0.1 2</size>
            </plane>
          </geometry>
          <material>
            <script>
              <uri>file://media/materials/scripts/gazebo.material</uri>
              <name>Gazebo/Yellow</name>
            </script>
          </material>
        </visual>
        <self_collide>0</self_collide>
        <kinematic>0</kinematic>
        <gravity>1</gravity>
        <enable_wind>0</enable_wind>
      </link>
      <pose>0.128878 4.12399 0 0 -0 0</pose>
    </model>
    <model name='yellow line_5'>
      <static>1</static>
      <link name='link_ground'>
        <collision name='collision'>
          <geometry>
            <plane>
              <normal>0 0 1</normal>
              <size>0.1 1</size>
            </plane>
          </geometry>
          <surface>
            <friction>
              <ode>
                <mu>100</mu>
                <mu2>50</mu2>
              </ode>
              <torsional>
                <ode/>
              </torsional>
            </friction>
            <contact>
              <ode/>
            </contact>
            <bounce/>
          </surface>
          <max_contacts>10</max_contacts>
        </collision>
        <visual name='visual_ground'>
          <cast_shadows>0</cast_shadows>
          <geometry>
            <plane>
              <normal>0 0 1</normal>
              <size>0.1 1</size>
            </plane>
          </geometry>
          <material>
            <script>
              <uri>file://media/materials/scripts/gazebo.material</uri>
              <name>Gazebo/Yellow</name>
            </script>
          </material>
        </visual>
        <self_collide>0</self_collide>
        <kinematic>0</kinematic>
        <gravity>1</gravity>
        <enable_wind>0</enable_wind>
      </link>
      <pose>-0.755609 3.97803 0 0 -0 0</pose>
    </model>
    <model name='yellow line_7'>
      <static>1</static>
      <link name='link_ground'>
        <collision name='collision'>
          <geometry>
            <plane>
              <normal>0 0 1</normal>
              <size>0.1 8.2</size>
            </plane>
          </geometry>
          <surface>
            <friction>
              <ode>
                <mu>100</mu>
                <mu2>50</mu2>
              </ode>
              <torsional>
                <ode/>
              </torsional>
            </friction>
            <contact>
              <ode/>
            </contact>
            <bounce/>
          </surface>
          <max_contacts>10</max_contacts>
        </collision>
        <visual name='visual_ground'>
          <cast_shadows>0</cast_shadows>
          <geometry>
            <plane>
              <normal>0 0 1</normal>
              <size>0.1 8.2</size>
            </plane>
          </geometry>
          <material>
            <script>
              <uri>file://media/materials/scripts/gazebo.material</uri>
              <name>Gazebo/Yellow</name>
            </script>
          </material>
        </visual>
        <self_collide>0</self_collide>
        <kinematic>0</kinematic>
        <gravity>1</gravity>
        <enable_wind>0</enable_wind>
      </link>
      <pose>-0.94783 -0.211502 0 0 -0 0</pose>
    </model>
    <model name='yellow line_8'>
      <static>1</static>
      <link name='link_ground'>
        <collision name='collision'>
          <geometry>
            <plane>
              <normal>0 0 1</normal>
              <size>0.1 3.2</size>
            </plane>
          </geometry>
          <surface>
            <friction>
              <ode>
                <mu>100</mu>
                <mu2>50</mu2>
              </ode>
              <torsional>
                <ode/>
              </torsional>
            </friction>
            <contact>
              <ode/>
            </contact>
            <bounce/>
          </surface>
          <max_contacts>10</max_contacts>
        </collision>
        <visual name='visual_ground'>
          <cast_shadows>0</cast_shadows>
          <geometry>
            <plane>
              <normal>0 0 1</normal>
              <size>0.1 3.2</size>
            </plane>
          </geometry>
          <material>
            <script>
              <uri>file://media/materials/scripts/gazebo.material</uri>
              <name>Gazebo/Yellow</name>
            </script>
          </material>
        </visual>
        <self_collide>0</self_collide>
        <kinematic>0</kinematic>
        <gravity>1</gravity>
        <enable_wind>0</enable_wind>
      </link>
      <pose>-1.41006 -5.62796 0 0 -0 0</pose>
    </model>
    <model name='yellow line_9'>
      <static>1</static>
      <link name='link_ground'>
        <collision name='collision'>
          <geometry>
            <plane>
              <normal>0 0 1</normal>
              <size>0.1 3.2</size>
            </plane>
          </geometry>
          <surface>
            <friction>
              <ode>
                <mu>100</mu>
                <mu2>50</mu2>
              </ode>
              <torsional>
                <ode/>
              </torsional>
            </friction>
            <contact>
              <ode/>
            </contact>
            <bounce/>
          </surface>
          <max_contacts>10</max_contacts>
        </collision>
        <visual name='visual_ground'>
          <cast_shadows>0</cast_shadows>
          <geometry>
            <plane>
              <normal>0 0 1</normal>
              <size>0.1 3.2</size>
            </plane>
          </geometry>
          <material>
            <script>
              <uri>file://media/materials/scripts/gazebo.material</uri>
              <name>Gazebo/Yellow</name>
            </script>
          </material>
        </visual>
        <self_collide>0</self_collide>
        <kinematic>0</kinematic>
        <gravity>1</gravity>
        <enable_wind>0</enable_wind>
      </link>
      <pose>-1.21409 0.311502 0 0 -0 0</pose>
    </model>
    <state world_name='default'>
      <sim_time>1917 797000000</sim_time>
      <real_time>2480 819194912</real_time>
      <wall_time>1700826291 117092118</wall_time>
      <iterations>205890</iterations>
      <model name='crawler_gazebo'>
        <pose>-2.10572 -0.099595 0.386547 0.000185 -0.000299 -0.087535</pose>
        <scale>1 1 1</scale>
        <link name='base_link'>
          <pose>-2.10572 -0.099595 0.386547 0.000185 -0.000299 -0.087535</pose>
          <velocity>0.007414 0.10258 0.000711 -0.043298 0.021334 0.529547</velocity>
          <acceleration>3.86618 7.2195 4.26261 3.01243 0.309403 3.08702</acceleration>
          <wrench>587.655 1097.36 647.913 0 -0 0</wrench>
        </link>
        <link name='link_1'>
          <pose>-2.3578 -0.046696 0.067401 -3.14094 -1.25351 -0.088147</pose>
          <velocity>-0.027152 -0.044595 0.004116 -0.097979 -0.619896 0.529815</velocity>
          <acceleration>-86.5534 -39.341 -0.721527 -1.08575 0.436189 -2.99318</acceleration>
          <wrench>-12148.4 -5521.78 -101.271 0 -0 0</wrench>
        </link>
        <link name='link_10'>
          <pose>-2.34666 0.090712 0.449501 0.695046 0.000345 -2.48248</pose>
          <velocity>-0.07199 -0.00663 -0.002398 -0.366082 -0.227849 2.84</velocity>
          <acceleration>-138.466 -82.4697 -17.051 -2.22503 1.16606 -0.08963</acceleration>
          <wrench>-12.9302 -7.70115 -1.59225 0 -0 0</wrench>
        </link>
        <link name='link_2'>
          <pose>-2.17343 -0.062875 0.067448 -0.000218 -0.373221 3.05413</pose>
          <velocity>-0.019013 0.053147 0.00046 -0.043123 0.007844 0.529023</velocity>
          <acceleration>-78.3133 58.3571 -4.45153 1.56169 -0.532772 0.298913</acceleration>
          <wrench>-10991.8 8190.82 -624.804 0 -0 0</wrench>
        </link>
        <link name='link_3'>
          <pose>-2.36266 -0.102079 0.067381 3.14067 -1.37328 3.05497</pose>
          <velocity>0.002149 -0.047252 0.005971 0.033025 0.902501 0.529897</velocity>
          <acceleration>61.536 -52.5043 11.2144 1.19644 -0.901627 0.276122</acceleration>
          <wrench>8637 -7369.34 1574.02 0 -0 0</wrench>
        </link>
        <link name='link_4'>
          <pose>-2.1783 -0.118258 0.067444 3.14101 -1.26662 3.05461</pose>
          <velocity>0.010173 0.050439 0.003292 0.024421 0.802387 0.530462</velocity>
          <acceleration>69.6187 45.1812 8.50903 2.43662 -1.26713 0.303225</acceleration>
          <wrench>9771.47 6341.49 1194.3 0 -0 0</wrench>
        </link>
        <link name='link_9'>
          <pose>-2.35338 0.099412 0.4235 -1.57073 0.000349 -2.48249</pose>
          <velocity>-0.09713 -0.026937 -0.002624 -0.043974 0.020788 2.84003</velocity>
          <acceleration>-104.707 -16.2246 -2.81983 -1.12763 1.43118 2.09622</acceleration>
          <wrench>-5.03466 -0.780135 -0.135587 0 -0 0</wrench>
        </link>
      </model>
      <model name='yellow line_0'>
        <pose>1.21409 0 0 0 -0 1.57</pose>
        <scale>1 1 1</scale>
        <link name='link_ground'>
          <pose>1.21409 0 0 0 -0 1.57</pose>
          <velocity>0 0 0 0 -0 0</velocity>
          <acceleration>0 0 0 0 -0 0</acceleration>
          <wrench>0 0 0 0 -0 0</wrench>
        </link>
      </model>
      <model name='yellow line_1'>
        <pose>3.65 2.42 0 1e-06 -0 0.784999</pose>
        <scale>1 1 1</scale>
        <link name='link_ground'>
          <pose>3.65 2.42 0 1e-06 -0 0.784999</pose>
          <velocity>0 0 0 0 -0 0</velocity>
          <acceleration>0 0 0 0 -0 0</acceleration>
          <wrench>0 0 0 0 -0 0</wrench>
        </link>
      </model>
      <model name='yellow line_2'>
        <pose>4.58297 1 0 0 -0 0.7</pose>
        <scale>1 1 1</scale>
        <link name='link_ground'>
          <pose>4.58297 1 0 0 -0 0.7</pose>
          <velocity>0 0 0 0 -0 0</velocity>
          <acceleration>0 0 0 0 -0 0</acceleration>
          <wrench>0 0 0 0 -0 0</wrench>
        </link>
      </model>
      <model name='yellow line_3'>
        <pose>2.4 3.58 0 0 -0 0.684999</pose>
        <scale>1 1 1</scale>
        <link name='link_ground'>
          <pose>2.4 3.58 0 0 -0 0.684999</pose>
          <velocity>0 0 0 0 -0 0</velocity>
          <acceleration>0 0 0 0 -0 0</acceleration>
          <wrench>0 0 0 0 -0 0</wrench>
        </link>
      </model>
      <model name='yellow line_4'>
        <pose>0.72 4.3 0 0 -0 1.57</pose>
        <scale>1 1 1</scale>
        <link name='link_ground'>
          <pose>0.72 4.3 0 0 -0 1.57</pose>
          <velocity>0 0 0 0 -0 0</velocity>
          <acceleration>0 0 0 0 -0 0</acceleration>
          <wrench>0 0 0 0 -0 0</wrench>
        </link>
      </model>
      <model name='yellow line_5'>
        <pose>-0.82 4.06 0 1e-06 0.05 -1.285</pose>
        <scale>1 1 1</scale>
        <link name='link_ground'>
          <pose>-0.82 4.06 0 1e-06 0.05 -1.285</pose>
          <velocity>0 0 0 0 -0 0</velocity>
          <acceleration>0 0 0 0 -0 0</acceleration>
          <wrench>0 0 0 0 -0 0</wrench>
        </link>
      </model>
      <model name='yellow line_7'>
        <pose>1.21409 0 0 0 -0 1.57</pose>
        <scale>1 1 1</scale>
        <link name='link_ground'>
          <pose>1.21409 0 0 0 -0 1.57</pose>
          <velocity>0 0 0 0 -0 0</velocity>
          <acceleration>0 0 0 0 -0 0</acceleration>
          <wrench>0 0 0 0 -0 0</wrench>
        </link>
      </model>
      <model name='yellow line_8'>
        <pose>-2.75 3.2 0 0 0 -1.185</pose>
        <scale>1 1 1</scale>
        <link name='link_ground'>
          <pose>-2.75 3.2 0 0 0 -1.185</pose>
          <velocity>0 0 0 0 -0 0</velocity>
          <acceleration>0 0 0 0 -0 0</acceleration>
          <wrench>0 0 0 0 -0 0</wrench>
        </link>
      </model>
      <model name='yellow line_9'>
        <pose>-3.61409 1.5115 0 0 0.449999 0.45</pose>
        <scale>1 1 1</scale>
        <link name='link_ground'>
          <pose>-3.61409 1.5115 0 0 0.449999 0.45</pose>
          <velocity>0 0 0 0 -0 0</velocity>
          <acceleration>0 0 0 0 -0 0</acceleration>
          <wrench>0 0 0 0 -0 0</wrench>
        </link>
      </model>
      <light name='sun'>
        <pose>0 0 10 0 -0 0</pose>
      </light>
    </state>
    <gui fullscreen='0'>
      <camera name='user_camera'>
        <pose>-0.019163 1.8608 10.5017 2e-05 1.5698 -1.52158</pose>
        <view_controller>orbit</view_controller>
        <projection_type>perspective</projection_type>
      </camera>
    </gui>
    <wind/>
    <model name='crawler_gazebo'>
      <link name='base_link'>
        <inertial>
          <pose>-0.165236 -0.014843 -0.174025 0 -0 0</pose>
          <mass>151.999</mass>
          <inertia>
            <ixx>1.50438</ixx>
            <ixy>0.0228319</ixy>
            <ixz>-0.0272521</ixz>
            <iyy>0.624991</iyy>
            <iyz>-0.0203304</iyz>
            <izz>1.78669</izz>
          </inertia>
        </inertial>
        <collision name='base_link_collision'>
          <pose>0 0 0 0 -0 0</pose>
          <geometry>
            <mesh>
              <scale>1 1 1</scale>
              <uri>/home/ws/Octo_crawler/src/crawler_gazebo/meshes/base_link.STL</uri>
            </mesh>
          </geometry>
          <max_contacts>10</max_contacts>
          <surface>
            <contact>
              <ode/>
            </contact>
            <bounce/>
            <friction>
              <torsional>
                <ode/>
              </torsional>
              <ode/>
            </friction>
          </surface>
        </collision>
        <collision name='base_link_fixed_joint_lump__link_13_collision_1'>
          <pose>-0.0428 0.0028 -0.25555 0 -0 0</pose>
          <geometry>
            <mesh>
              <scale>1 1 1</scale>
              <uri>/home/ws/Octo_crawler/src/crawler_gazebo/meshes/link_13.STL</uri>
            </mesh>
          </geometry>
          <max_contacts>10</max_contacts>
          <surface>
            <contact>
              <ode/>
            </contact>
            <bounce/>
            <friction>
              <torsional>
                <ode/>
              </torsional>
              <ode/>
            </friction>
          </surface>
        </collision>
        <collision name='base_link_fixed_joint_lump__link_12_collision_2'>
          <pose>-0.2838 0.0028 -0.25555 0 0 -3.14159</pose>
          <geometry>
            <mesh>
              <scale>1 1 1</scale>
              <uri>/home/ws/Octo_crawler/src/crawler_gazebo/meshes/link_12.STL</uri>
            </mesh>
          </geometry>
          <max_contacts>10</max_contacts>
          <surface>
            <contact>
              <ode/>
            </contact>
            <bounce/>
            <friction>
              <torsional>
                <ode/>
              </torsional>
              <ode/>
            </friction>
          </surface>
        </collision>
        <collision name='base_link_fixed_joint_lump__link_11_collision_3'>
          <pose>0 0 0 0 -0 0</pose>
          <geometry>
            <mesh>
              <scale>1 1 1</scale>
              <uri>/home/ws/Octo_crawler/src/crawler_gazebo/meshes/link_11.STL</uri>
            </mesh>
          </geometry>
          <max_contacts>10</max_contacts>
          <surface>
            <contact>
              <ode/>
            </contact>
            <bounce/>
            <friction>
              <torsional>
                <ode/>
              </torsional>
              <ode/>
            </friction>
          </surface>
        </collision>
        <visual name='base_link_visual'>
          <pose>0 0 0 0 -0 0</pose>
          <geometry>
            <mesh>
              <scale>1 1 1</scale>
              <uri>/home/ws/Octo_crawler/src/crawler_gazebo/meshes/base_link.STL</uri>
            </mesh>
          </geometry>
        </visual>
        <visual name='base_link_fixed_joint_lump__link_13_visual_1'>
          <pose>-0.0428 0.0028 -0.25555 0 -0 0</pose>
          <geometry>
            <mesh>
              <scale>1 1 1</scale>
              <uri>/home/ws/Octo_crawler/src/crawler_gazebo/meshes/link_13.STL</uri>
            </mesh>
          </geometry>
        </visual>
        <visual name='base_link_fixed_joint_lump__camera_link_visual_2'>
          <pose>0.0828 0.0028 0.13555 0 0.85 0</pose>
          <geometry>
            <mesh>
              <scale>1 1 1</scale>
              <uri>/home/ws/Octo_crawler/src/crawler_gazebo/meshes/link_12.STL</uri>
            </mesh>
          </geometry>
        </visual>
        <visual name='base_link_fixed_joint_lump__link_12_visual_3'>
          <pose>-0.2838 0.0028 -0.25555 0 0 -3.14159</pose>
          <geometry>
            <mesh>
              <scale>1 1 1</scale>
              <uri>/home/ws/Octo_crawler/src/crawler_gazebo/meshes/link_12.STL</uri>
            </mesh>
          </geometry>
        </visual>
        <visual name='base_link_fixed_joint_lump__imu_link_visual_4'>
          <pose>-0.1225 0.1225 -0.2 0 -0 0</pose>
          <geometry>
            <box>
              <size>0.01 0.03 0.03</size>
            </box>
          </geometry>
        </visual>
        <visual name='base_link_fixed_joint_lump__link_11_visual_5'>
          <pose>0 0 0 0 -0 0</pose>
          <geometry>
            <mesh>
              <scale>1 1 1</scale>
              <uri>/home/ws/Octo_crawler/src/crawler_gazebo/meshes/link_11.STL</uri>
            </mesh>
          </geometry>
        </visual>
        <sensor name='camera' type='camera'>
          <update_rate>30</update_rate>
          <visualize>1</visualize>
          <camera name='head'>
            <horizontal_fov>0.362634</horizontal_fov>
            <image>
              <width>800</width>
              <height>800</height>
              <format>R8G8B8</format>
            </image>
            <clip>
              <near>0.02</near>
              <far>8</far>
            </clip>
            <noise>
              <type>gaussian</type>
              <mean>0</mean>
              <stddev>0.007</stddev>
            </noise>
          </camera>
          <plugin name='crawler_camera_controller' filename='libgazebo_ros_camera.so'>
            <alwaysOn>1</alwaysOn>
            <updateRate>0.0</updateRate>
            <cameraName>camera1</cameraName>
            <imageTopicName>image_raw</imageTopicName>
            <cameraInfoTopicName>camera_info</cameraInfoTopicName>
            <frameName>camera_link_optical</frameName>
            <hackBaseline>0.07</hackBaseline>
            <distortionK1>0.0</distortionK1>
            <distortionK2>0.0</distortionK2>
            <distortionK3>0.0</distortionK3>
            <distortionT1>0.0</distortionT1>
            <distortionT2>0.0</distortionT2>
            <robotNamespace>/</robotNamespace>
          </plugin>
          <pose>0.0828 0.0028 0.13555 0 0.85 0</pose>
        </sensor>
        <gravity>1</gravity>
        <sensor name='imu_sensor' type='imu'>
          <always_on>1</always_on>
          <update_rate>100</update_rate>
          <visualize>1</visualize>
          <topic>imu</topic>
          <plugin name='imu_plugin' filename='libgazebo_ros_imu_sensor.so'>
            <topicName>imu</topicName>
            <bodyName>imu_link</bodyName>
            <updateRateHZ>10.0</updateRateHZ>
            <gaussianNoise>2e-3</gaussianNoise>
            <xyzOffset>0 0 0</xyzOffset>
            <rpyOffset>0 0 0</rpyOffset>
            <frameName>imu_link</frameName>
            <initialOrientationAsReference>0</initialOrientationAsReference>
            <robotNamespace>/</robotNamespace>
          </plugin>
          <pose>-0.1225 0.1225 -0.2 0 -0 0</pose>
          <imu/>
        </sensor>
        <self_collide>0</self_collide>
        <enable_wind>0</enable_wind>
        <kinematic>0</kinematic>
      </link>
      <joint name='gimble_pan' type='revolute'>
        <pose relative_to='base_link'>-0.2641 0.1766 0.037 -1.5708 0 1.5502</pose>
        <parent>base_link</parent>
        <child>link_9</child>
        <axis>
          <xyz>0 1 0</xyz>
          <limit>
            <effort>10</effort>
            <velocity>0.1</velocity>
            <lower>-1e+16</lower>
            <upper>1e+16</upper>
          </limit>
          <dynamics>
            <spring_reference>0</spring_reference>
            <spring_stiffness>0</spring_stiffness>
          </dynamics>
        </axis>
      </joint>
      <link name='link_9'>
        <pose relative_to='gimble_pan'>0 0 0 0 -0 0</pose>
        <inertial>
          <pose>-0.0045 -0.015589 -3.6e-05 0 -0 0</pose>
          <mass>0.0480834</mass>
          <inertia>
            <ixx>2.51445e-05</ixx>
            <ixy>-2.25271e-06</ixy>
            <ixz>-4.22764e-08</ixz>
            <iyy>5.10291e-05</iyy>
            <iyz>-1.79894e-08</iyz>
            <izz>3.86815e-05</izz>
          </inertia>
        </inertial>
        <collision name='link_9_collision'>
          <pose>0 0 0 0 -0 0</pose>
          <geometry>
            <mesh>
              <scale>1 1 1</scale>
              <uri>/home/ws/Octo_crawler/src/crawler_gazebo/meshes/link_9.STL</uri>
            </mesh>
          </geometry>
          <max_contacts>10</max_contacts>
          <surface>
            <contact>
              <ode/>
            </contact>
            <bounce/>
            <friction>
              <torsional>
                <ode/>
              </torsional>
              <ode/>
            </friction>
          </surface>
        </collision>
        <visual name='link_9_visual'>
          <pose>0 0 0 0 -0 0</pose>
          <geometry>
            <mesh>
              <scale>1 1 1</scale>
              <uri>/home/ws/Octo_crawler/src/crawler_gazebo/meshes/link_9.STL</uri>
            </mesh>
          </geometry>
        </visual>
        <self_collide>0</self_collide>
        <enable_wind>0</enable_wind>
        <kinematic>0</kinematic>
      </link>
      <joint name='gimble_tilt' type='revolute'>
        <pose relative_to='link_9'>0 -0.026 0.011 0.390908 -0 0</pose>
        <parent>link_9</parent>
        <child>link_10</child>
        <axis>
          <xyz>-1 0 0</xyz>
          <limit>
            <effort>10</effort>
            <velocity>0.1</velocity>
            <lower>-1e+16</lower>
            <upper>1e+16</upper>
          </limit>
          <dynamics>
            <spring_reference>0</spring_reference>
            <spring_stiffness>0</spring_stiffness>
          </dynamics>
        </axis>
      </joint>
      <link name='link_10'>
        <pose relative_to='gimble_tilt'>0 0 0 0 -0 0</pose>
        <inertial>
          <pose>0.004241 -0.037343 0.009239 0 -0 0</pose>
          <mass>0.0933816</mass>
          <inertia>
            <ixx>1.94022e-05</ixx>
            <ixy>2.51303e-07</ixy>
            <ixz>7.82292e-07</ixz>
            <iyy>0.000107794</iyy>
            <iyz>1.41516e-06</iyz>
            <izz>0.000116316</izz>
          </inertia>
        </inertial>
        <collision name='link_10_collision'>
          <pose>0 0 0 0 -0 0</pose>
          <geometry>
            <mesh>
              <scale>1 1 1</scale>
              <uri>/home/ws/Octo_crawler/src/crawler_gazebo/meshes/link_10.STL</uri>
            </mesh>
          </geometry>
          <max_contacts>10</max_contacts>
          <surface>
            <contact>
              <ode/>
            </contact>
            <bounce/>
            <friction>
              <torsional>
                <ode/>
              </torsional>
              <ode/>
            </friction>
          </surface>
        </collision>
        <visual name='link_10_visual'>
          <pose>0 0 0 0 -0 0</pose>
          <geometry>
            <mesh>
              <scale>1 1 1</scale>
              <uri>/home/ws/Octo_crawler/src/crawler_gazebo/meshes/link_10.STL</uri>
            </mesh>
          </geometry>
        </visual>
        <self_collide>0</self_collide>
        <enable_wind>0</enable_wind>
        <kinematic>0</kinematic>
      </link>
      <joint name='left_back_wheel' type='revolute'>
        <pose relative_to='base_link'>-0.070756 -0.024997 -0.31908 0 0.30744 0</pose>
        <parent>base_link</parent>
        <child>link_4</child>
        <axis>
          <xyz>0 1 0</xyz>
          <limit>
            <effort>10</effort>
            <velocity>10</velocity>
            <lower>-1e+16</lower>
            <upper>1e+16</upper>
          </limit>
          <dynamics>
            <spring_reference>0</spring_reference>
            <spring_stiffness>0</spring_stiffness>
          </dynamics>
        </axis>
      </joint>
      <link name='link_4'>
        <pose relative_to='left_back_wheel'>0 0 0 0 -0 0</pose>
        <inertial>
          <pose>2.6e-05 -0.112526 7.2e-05 0 -0 0</pose>
          <mass>140.357</mass>
          <inertia>
            <ixx>0.156349</ixx>
            <ixy>0.000120005</ixy>
            <ixz>-0.000132718</ixz>
            <iyy>0.269361</iyy>
            <iyz>-1.43448e-05</iyz>
            <izz>0.155458</izz>
          </inertia>
        </inertial>
        <collision name='link_4_collision'>
          <pose>0 0 0 0 -0 0</pose>
          <geometry>
            <mesh>
              <scale>1 1 1</scale>
              <uri>/home/ws/Octo_crawler/src/crawler_gazebo/meshes/link_4.STL</uri>
            </mesh>
          </geometry>
          <max_contacts>10</max_contacts>
          <surface>
            <contact>
              <ode/>
            </contact>
            <bounce/>
            <friction>
              <torsional>
                <ode/>
              </torsional>
              <ode/>
            </friction>
          </surface>
        </collision>
        <visual name='link_4_visual'>
          <pose>0 0 0 0 -0 0</pose>
          <geometry>
            <mesh>
              <scale>1 1 1</scale>
              <uri>/home/ws/Octo_crawler/src/crawler_gazebo/meshes/link_4.STL</uri>
            </mesh>
          </geometry>
        </visual>
        <self_collide>0</self_collide>
        <enable_wind>0</enable_wind>
        <kinematic>0</kinematic>
      </link>
      <joint name='left_front_wheel' type='revolute'>
        <pose relative_to='base_link'>-0.25584 -0.024997 -0.31908 0 -0.76081 0</pose>
        <parent>base_link</parent>
        <child>link_3</child>
        <axis>
          <xyz>0 1 0</xyz>
          <limit>
            <effort>10</effort>
            <velocity>10</velocity>
            <lower>-1e+16</lower>
            <upper>1e+16</upper>
          </limit>
          <dynamics>
            <spring_reference>0</spring_reference>
            <spring_stiffness>0</spring_stiffness>
          </dynamics>
        </axis>
      </joint>
      <link name='link_3'>
        <pose relative_to='left_front_wheel'>0 0 0 0 -0 0</pose>
        <inertial>
          <pose>2.6e-05 -0.112526 7.2e-05 0 -0 0</pose>
          <mass>140.357</mass>
          <inertia>
            <ixx>0.156349</ixx>
            <ixy>0.000120005</ixy>
            <ixz>-0.000132718</ixz>
            <iyy>0.269361</iyy>
            <iyz>-1.43448e-05</iyz>
            <izz>0.155458</izz>
          </inertia>
        </inertial>
        <collision name='link_3_collision'>
          <pose>0 0 0 0 -0 0</pose>
          <geometry>
            <mesh>
              <scale>1 1 1</scale>
              <uri>/home/ws/Octo_crawler/src/crawler_gazebo/meshes/link_3.STL</uri>
            </mesh>
          </geometry>
          <max_contacts>10</max_contacts>
          <surface>
            <contact>
              <ode/>
            </contact>
            <bounce/>
            <friction>
              <torsional>
                <ode/>
              </torsional>
              <ode/>
            </friction>
          </surface>
        </collision>
        <visual name='link_3_visual'>
          <pose>0 0 0 0 -0 0</pose>
          <geometry>
            <mesh>
              <scale>1 1 1</scale>
              <uri>/home/ws/Octo_crawler/src/crawler_gazebo/meshes/link_3.STL</uri>
            </mesh>
          </geometry>
        </visual>
        <self_collide>0</self_collide>
        <enable_wind>0</enable_wind>
        <kinematic>0</kinematic>
      </link>
      <joint name='right_back_wheel' type='revolute'>
        <pose relative_to='base_link'>-0.070756 0.030598 -0.31908 0 0.21622 -3.14159</pose>
        <parent>base_link</parent>
        <child>link_2</child>
        <axis>
          <xyz>0 1 0</xyz>
          <limit>
            <effort>10</effort>
            <velocity>10</velocity>
            <lower>-1e+16</lower>
            <upper>1e+16</upper>
          </limit>
          <dynamics>
            <spring_reference>0</spring_reference>
            <spring_stiffness>0</spring_stiffness>
          </dynamics>
        </axis>
      </joint>
      <link name='link_2'>
        <pose relative_to='right_back_wheel'>0 0 0 0 -0 0</pose>
        <inertial>
          <pose>2.6e-05 -0.112526 7.2e-05 0 -0 0</pose>
          <mass>140.357</mass>
          <inertia>
            <ixx>0.156349</ixx>
            <ixy>0.000120005</ixy>
            <ixz>-0.000132718</ixz>
            <iyy>0.269361</iyy>
            <iyz>-1.43448e-05</iyz>
            <izz>0.155458</izz>
          </inertia>
        </inertial>
        <collision name='link_2_collision'>
          <pose>0 0 0 0 -0 0</pose>
          <geometry>
            <mesh>
              <scale>1 1 1</scale>
              <uri>/home/ws/Octo_crawler/src/crawler_gazebo/meshes/link_2.STL</uri>
            </mesh>
          </geometry>
          <max_contacts>10</max_contacts>
          <surface>
            <contact>
              <ode/>
            </contact>
            <bounce/>
            <friction>
              <torsional>
                <ode/>
              </torsional>
              <ode/>
            </friction>
          </surface>
        </collision>
        <visual name='link_2_visual'>
          <pose>0 0 0 0 -0 0</pose>
          <geometry>
            <mesh>
              <scale>1 1 1</scale>
              <uri>/home/ws/Octo_crawler/src/crawler_gazebo/meshes/link_2.STL</uri>
            </mesh>
          </geometry>
        </visual>
        <self_collide>0</self_collide>
        <enable_wind>0</enable_wind>
        <kinematic>0</kinematic>
      </link>
      <joint name='right_front_wheel' type='revolute'>
        <pose relative_to='base_link'>-0.25584 0.030598 -0.31908 0 -0.42439 -3.14159</pose>
        <parent>base_link</parent>
        <child>link_1</child>
        <axis>
          <xyz>0 1 0</xyz>
          <limit>
            <effort>10</effort>
            <velocity>10</velocity>
            <lower>-1e+16</lower>
            <upper>1e+16</upper>
          </limit>
          <dynamics>
            <spring_reference>0</spring_reference>
            <spring_stiffness>0</spring_stiffness>
          </dynamics>
        </axis>
      </joint>
      <link name='link_1'>
        <pose relative_to='right_front_wheel'>0 0 0 0 -0 0</pose>
        <inertial>
          <pose>2.6e-05 -0.112526 7.2e-05 0 -0 0</pose>
          <mass>140.357</mass>
          <inertia>
            <ixx>0.156349</ixx>
            <ixy>0.000120005</ixy>
            <ixz>-0.000132718</ixz>
            <iyy>0.269361</iyy>
            <iyz>-1.43448e-05</iyz>
            <izz>0.155458</izz>
          </inertia>
        </inertial>
        <collision name='link_1_collision'>
          <pose>0 0 0 0 -0 0</pose>
          <geometry>
            <mesh>
              <scale>1 1 1</scale>
              <uri>/home/ws/Octo_crawler/src/crawler_gazebo/meshes/link_1.STL</uri>
            </mesh>
          </geometry>
          <max_contacts>10</max_contacts>
          <surface>
            <contact>
              <ode/>
            </contact>
            <bounce/>
            <friction>
              <torsional>
                <ode/>
              </torsional>
              <ode/>
            </friction>
          </surface>
        </collision>
        <visual name='link_1_visual'>
          <pose>0 0 0 0 -0 0</pose>
          <geometry>
            <mesh>
              <scale>1 1 1</scale>
              <uri>/home/ws/Octo_crawler/src/crawler_gazebo/meshes/link_1.STL</uri>
            </mesh>
          </geometry>
        </visual>
        <self_collide>0</self_collide>
        <enable_wind>0</enable_wind>
        <kinematic>0</kinematic>
      </link>
      <static>0</static>
      <plugin name='object_controller' filename='libgazebo_ros_planar_move.so'>
        <commandTopic>cmd_vel</commandTopic>
        <odometryTopic>odom</odometryTopic>
        <odometryFrame>odom</odometryFrame>
        <odometryRate>20.0</odometryRate>
        <robotBaseFrame>base_link</robotBaseFrame>
        <robotNamespace>/</robotNamespace>
      </plugin>
      <pose>0 0 0 0 -0 0</pose>
    </model>
  </world>
</sdf>